Workbook

Sheet POW
B3: Project Name: | C3: Proposed /Construction of Adidtional Footing/ Column & Beam for Archbishop's Palace
B4: Location: | C4: D. Jakosalem St., Cebu City
B6: PROGRAM OF WORKS (POW)
B7: ITEM NO. | C7: DESCRIPTION | D7: QUANTITY | E7: UNIT | F7: UNIT COST | G7: AMOUNT | H7: MATERIALS | I7: EQUIPMENT | J7: MANPOWER | K7: M/D | L7: OCM | M7: PROFIT | N7: VAT (Excluded M/D) | O7: TOTAL AMOUNT
B8: ITEMS FROM BILL OF QUANTITIES (BOQ) | K8: 0.01 | L8: 0.12 | M8: 0.08 | N8: 0.05
B9: I. | C9: General Requirements
B10: I.1 | C10: Health & Safety | D10: =+I.1!C11 -> 6 | E10: =+I.1!E11 -> months | F10: =+I.1!G42 -> 4200 | G10: =+D10*F10 -> 25200 | H10: =+I.1!G21 -> 24000 | I10: =+I.1!G27 -> 0 | J10: =+I.1!G32 -> 0 | K10: 0 | L10: 0 | M10: 0 | N10: =+SUM(H10:J10,L10:M10)*$N$8 -> 1200 | O10: =+SUM(H10:N10) -> 25200
B11: I.2 | C11: Material Testing | D11: =+I.2!C11 -> 1 | E11: =+I.2!E11 -> lot | F11: =+I.2!G41 -> 12600 | G11: =+D11*F11 -> 12600 | H11: =+I.2!G21 -> 10000 | I11: =+I.2!G27 -> 0 | J11: =+I.2!G31 -> 0 | K11: 0 | L11: =+SUM(H11:J11)*$L$8 -> 1200 | M11: =+SUM(H11:J11)*$M$8 -> 800 | N11: =+SUM(H11:J11,L11:M11)*$N$8 -> 600 | O11: =+SUM(H11:N11) -> 12600
B12: II. | C12: Site Works | G12: =+D12*F12 -> 0 | K12: =+SUM(H12:J12)*$K$8 -> 0 | L12: =+SUM(H12:J12)*$L$8 -> 0 | M12: =+SUM(H12:J12)*$M$8 -> 0 | N12: =+SUM(H12:J12,L12:M12)*$N$8 -> 0 | O12: =+SUM(H12:N12) -> 0
B13: II.1 | C13: Site Lay-out/Clearing & Grubbing | D13: =+II.1!C11 -> 1 | E13: =+II.1!E11 -> lot | F13: =+II.1!G42 -> 31750 | G13: =+D13*F13 -> 31750 | H13: =+II.1!G21 -> 0 | I13: =+II.1!G27 -> 2000 | J13: =+II.1!G32 -> 23000 | K13: =+SUM(H13:J13)*$K$8 -> 250 | L13: =+SUM(H13:J13)*$L$8 -> 3000 | M13: =+SUM(H13:J13)*$M$8 -> 2000 | N13: =+SUM(H13:J13,L13:M13)*$N$8 -> 1500 | O13: =+SUM(H13:N13) -> 31750
B14: II.2 | C14: Demolition & Restoration | D14: =+II.2!C11 -> 91.9989 | E14: =+II.2!E11 -> sq.m. | F14: =+II.2!G46 -> 746.11499 | G14: =+D14*F14 -> 68641.759 | H14: =+II.2!G21 -> 0 | I14: =+II.2!G29 -> 32900 | J14: =+II.2!G36 -> 21148.629 | K14: =+SUM(H14:J14)*$K$8 -> 540.48629 | L14: =+SUM(H14:J14)*$L$8 -> 6485.8354 | M14: =+SUM(H14:J14)*$M$8 -> 4323.8903 | N14: =+SUM(H14:J14,L14:M14)*$N$8 -> 3242.9177 | O14: =+SUM(H14:N14) -> 68641.759
B15: II.3 | C15: Excavation | D15: =+II.3!C11 -> 173.2608 | E15: =+II.3!E11 -> cu.m. | F15: =+II.3!G44 -> 948.26667 | G15: =+D15*F15 -> 164297.44 | H15: =+II.3!G21 -> 0 | I15: =+II.3!G27 -> 25411.584 | J15: =+II.3!G34 -> 103956.48 | K15: =+SUM(H15:J15)*$K$8 -> 1293.6806 | L15: =+SUM(H15:J15)*$L$8 -> 15524.168 | M15: =+SUM(H15:J15)*$M$8 -> 10349.445 | N15: =+SUM(H15:J15,L15:M15)*$N$8 -> 7762.0838 | O15: =+SUM(H15:N15) -> 164297.44
B16: II.4 | C16: Backfill & Fill | D16: =+II.4!C11 -> 170.3808 | E16: =+II.4!E11 -> cu.m. | F16: =+II.4!G45 -> 716.84444 | G16: =+D16*F16 -> 122136.53 | H16: =+II.4!G21 -> 0 | I16: =+II.4!G28 -> 28018.176 | J16: =+II.4!G35 -> 68152.32 | K16: =+SUM(H16:J16)*$K$8 -> 961.70496 | L16: =+SUM(H16:J16)*$L$8 -> 11540.46 | M16: =+SUM(H16:J16)*$M$8 -> 7693.6397 | N16: =+SUM(H16:J16,L16:M16)*$N$8 -> 5770.2298 | O16: =+SUM(H16:N16) -> 122136.53
B17: II.5 | C17: Temporary Fence | D17: =+#REF! -> #REF! | E17: =+#REF! -> #REF! | F17: =+#REF! -> #REF! | G17: =+D17*F17 -> #REF! | H17: =+#REF! -> #REF! | I17: =+#REF! -> #REF! | J17: =+#REF! -> #REF! | K17: =+SUM(H17:J17)*$K$8 -> #REF! | L17: =+SUM(H17:J17)*$L$8 -> #REF! | M17: =+SUM(H17:J17)*$M$8 -> #REF! | N17: =+SUM(H17:J17,L17:M17)*$N$8 -> #REF! | O17: =+SUM(H17:N17) -> #REF!
B18: III. | C18: Formworks & Scaffoldings (Rental) | D18: =+III.!C9 -> 6 | E18: =+III.!E9 -> months | F18: =+III.!G39 -> 15750 | G18: =+D18*F18 -> 94500 | H18: =+III.!G19 -> 90000 | I18: =+III.!G24 -> 0 | J18: =+III.!G29 -> 0 | K18: 0 | L18: 0 | M18: 0 | N18: =+SUM(H18:J18,L18:M18)*$N$8 -> 4500 | O18: =+SUM(H18:N18) -> 94500
B19: IV. | C19: Concrete Works | G19: =+D19*F19 -> 0 | K19: =+SUM(H19:J19)*$K$8 -> 0 | L19: =+SUM(H19:J19)*$L$8 -> 0 | M19: =+SUM(H19:J19)*$M$8 -> 0 | N19: =+SUM(H19:J19,L19:M19)*$N$8 -> 0 | O19: =+SUM(H19:N19) -> 0
B20: IV.1 | C20: Fabrication of Reinforcing Bars for Footing, Columns & Beams | D20: =+IV.1!C11 -> 1 | E20: =+IV.1!E11 -> lot | F20: 500000 | G20: =+D20*F20 -> 500000 | H20: =+IV.1!G24 -> 1280000 | I20: =+IV.1!G32 -> 19000.788 | J20: =+IV.1!G40 -> 247500 | K20: =+SUM(H20:J20)*$K$8 -> 15465.008 | L20: =+SUM(H20:J20)*$L$8 -> 185580.09 | M20: =+SUM(H20:J20)*$M$8 -> 123720.06 | N20: =+SUM(H20:J20,L20:M20)*$N$8 -> 92790.047 | O20: =+SUM(H20:N20) -> 1964056
B21: IV.2 | C21: Cast-in-place Concrete (3000 psi) for Footing, Columns & Beams | D21: =+IV.2!C11 -> 187.64622 | E21: =+IV.2!E11 -> cu.m. | F21: =+IV.2!G49 -> 11706.502 | G21: =+D21*F21 -> 2196681 | H21: =+IV.2!G23 -> 1255208.9 | I21: =+IV.2!G31 -> 227711.2 | J21: =+IV.2!G39 -> 246750 | K21: =+SUM(H21:J21)*$K$8 -> 17296.701 | L21: =+SUM(H21:J21)*$L$8 -> 207560.41 | M21: =+SUM(H21:J21)*$M$8 -> 138373.6 | N21: =+SUM(H21:J21,L21:M21)*$N$8 -> 103780.2 | O21: =+SUM(H21:N21) -> 2196681
B22: IV.3 | C22: Plastering | D22: =+IV.3!C11 -> 208.9752 | E22: =+IV.3!E11 -> sq.m. | F22: =+IV.3!G46 -> 1276.4849 | G22: =+D22*F22 -> 266753.68 | H22: =+IV.3!G22 -> 113870 | I22: =+IV.3!G28 -> 9970 | J22: =+IV.3!G36 -> 86202.27 | K22: =+SUM(H22:J22)*$K$8 -> 2100.4227 | L22: =+SUM(H22:J22)*$L$8 -> 25205.072 | M22: =+SUM(H22:J22)*$M$8 -> 16803.382 | N22: =+SUM(H22:J22,L22:M22)*$N$8 -> 12602.536 | O22: =+SUM(H22:N22) -> 266753.68
B23: V. | C23: Masonry Works | G23: =+D23*F23 -> 0 | K23: =+SUM(H23:J23)*$K$8 -> 0 | L23: =+SUM(H23:J23)*$L$8 -> 0 | M23: =+SUM(H23:J23)*$M$8 -> 0 | N23: =+SUM(H23:J23,L23:M23)*$N$8 -> 0 | O23: =+SUM(H23:N23) -> 0
B24: V.1 | C24: 6" Concrete Hollow Blocks | D24: =+V.1!C11 -> 203.6475 | E24: =+V.1!E11 -> sq.m. | F24: =+V.1!G48 -> 1155.3113 | G24: =+D24*F24 -> 235276.25 | H24: =+V.1!G24 -> 54050 | I24: =+V.1!G30 -> 5200 | J24: =+V.1!G38 -> 126006.89 | K24: =+SUM(H24:J24)*$K$8 -> 1852.5689 | L24: =+SUM(H24:J24)*$L$8 -> 22230.827 | M24: =+SUM(H24:J24)*$M$8 -> 14820.551 | N24: =+SUM(H24:J24,L24:M24)*$N$8 -> 11115.413 | O24: =+SUM(H24:N24) -> 235276.25
B25: V.2 | C25: 4" Concrete Hollow Blocks | D25: =+V.2!C11 -> 269.325 | E25: =+V.2!E11 -> sq.m. | F25: =+V.2!G49 -> 1001.356 | G25: =+D25*F25 -> 269690.22 | H25: =+V.2!G25 -> 69250 | I25: =+V.2!G31 -> 2772 | J25: =+V.2!G39 -> 140332.5 | K25: =+SUM(H25:J25)*$K$8 -> 2123.545 | L25: =+SUM(H25:J25)*$L$8 -> 25482.54 | M25: =+SUM(H25:J25)*$M$8 -> 16988.36 | N25: =+SUM(H25:J25,L25:M25)*$N$8 -> 12741.27 | O25: =+SUM(H25:N25) -> 269690.22
B26: V.3 | C26: Plastering | D26: =+#REF! -> #REF! | E26: =+#REF! -> #REF! | F26: =+#REF! -> #REF! | G26: =+D26*F26 -> #REF! | H26: =+#REF! -> #REF! | I26: =+#REF! -> #REF! | J26: =+#REF! -> #REF! | K26: =+SUM(H26:J26)*$K$8 -> #REF! | L26: =+SUM(H26:J26)*$L$8 -> #REF! | M26: =+SUM(H26:J26)*$M$8 -> #REF! | N26: =+SUM(H26:J26,L26:M26)*$N$8 -> #REF! | O26: =+SUM(H26:N26) -> #REF!
B27: VI. | C27: Ceiling Works | D27: =+VI.!C9 -> 202.923 | E27: =+VI.!E9 -> sq.m. | F27: =+VI.!G49 -> 1527.0401 | G27: =+D27*F27 -> 309871.57 | H27: =+VI.!G25 -> 160086.16 | I27: =+VI.!G31 -> 9657.2 | J27: =+VI.!G39 -> 74250 | K27: =+SUM(H27:J27)*$K$8 -> 2439.9336 | L27: =+SUM(H27:J27)*$L$8 -> 29279.203 | M27: =+SUM(H27:J27)*$M$8 -> 19519.469 | N27: =+SUM(H27:J27,L27:M27)*$N$8 -> 14639.602 | O27: =+SUM(H27:N27) -> 309871.57
B28: VII. | C28: Roofing Works | G28: =+D28*F28 -> 0 | K28: =+SUM(H28:J28)*$K$8 -> 0 | L28: =+SUM(H28:J28)*$L$8 -> 0 | M28: =+SUM(H28:J28)*$M$8 -> 0 | N28: =+SUM(H28:J28,L28:M28)*$N$8 -> 0 | O28: =+SUM(H28:N28) -> 0
B29: VII.1 | C29: Trussess | D29: =+VII.1!C11 -> 219.605 | E29: =+VII.1!E11 -> ln.m. | F29: =+VII.1!G48 -> 821.68748 | G29: =+D29*F29 -> 180446.68 | H29: =+VII.1!G22 -> 54484 | I29: =+VII.1!G30 -> 28200 | J29: =+VII.1!G38 -> 59400 | K29: =+SUM(H29:J29)*$K$8 -> 1420.84 | L29: =+SUM(H29:J29)*$L$8 -> 17050.08 | M29: =+SUM(H29:J29)*$M$8 -> 11366.72 | N29: =+SUM(H29:J29,L29:M29)*$N$8 -> 8525.04 | O29: =+SUM(H29:N29) -> 180446.68
B30: VII.2 | C30: Corrugated G.I. Sheet Guage 22 | D30: =+VII.2!C11 -> 199.21671 | E30: =+VII.2!E11 -> sq.m. | F30: =+VII.2!G47 -> 1329.4522 | G30: =+D30*F30 -> 264849.1 | H30: =+VII.2!G23 -> 115875 | I30: =+VII.2!G29 -> 6000 | J30: =+VII.2!G37 -> 86667.6 | K30: =+SUM(H30:J30)*$K$8 -> 2085.426 | L30: =+SUM(H30:J30)*$L$8 -> 25025.112 | M30: =+SUM(H30:J30)*$M$8 -> 16683.408 | N30: =+SUM(H30:J30,L30:M30)*$N$8 -> 12512.556 | O30: =+SUM(H30:N30) -> 264849.1
B31: VIII. | C31: Painting Works (Exclusive of Ceiling) | D31: =+VIII.!C9 -> 1 | E31: =+VIII.!E9 -> lot | F31: =+VIII.!G46 -> 381000 | G31: =+D31*F31 -> 381000 | H31: =+VIII.!G22 -> 300000 | I31: =+VIII.!G28 -> 0 | J31: =+VIII.!G36 -> 0 | K31: =+SUM(H31:J31)*$K$8 -> 3000 | L31: =+SUM(H31:J31)*$L$8 -> 36000 | M31: =+SUM(H31:J31)*$M$8 -> 24000 | N31: =+SUM(H31:J31,L31:M31)*$N$8 -> 18000 | O31: =+SUM(H31:N31) -> 381000
B32: TOTAL CONSTRUCTION COST: | G32: =+SUM(G10:G31) -> #REF! | H32: =+SUM(H10:H31) -> #REF! | I32: =+SUM(I10:I31) -> #REF! | J32: =+SUM(J10:J31) -> #REF! | K32: =+SUM(K10:K31) -> #REF! | L32: =+SUM(L10:L31) -> #REF! | M32: =+SUM(M10:M31) -> #REF! | N32: =+SUM(N10:N31) -> #REF! | O32: =+SUM(O10:O31) -> #REF!

Sheet BOQ
B3: Project Name: | C3: Proposed /Construction of 3 Storey 342 square meter Apartment Building
B4: Location: | C4: Brgy. Lamac, Consolacion, Cebu
B5: Contractor: | C5: EIDOX Development
B7: BILL OF QUANTITIES (BOQ)
B8: ITEM NO. | C8: DESCRIPTION | D8: QUANTITY | E8: UNIT | F8: UNIT COST | G8: AMOUNT
B9: I. | C9: General Requirements
B10: A.1 | C10: Mobilization/Demobilization | D10: 1 | E10: lot | F10: 165000 | G10: 165000
C11: Project Billboard and Signages | D11: 1 | E11: lot | F11: 18000 | G11: =+D11*F11 -> 18000
C12: Health and Safety | D12: 10 | E12: months | F12: 12000 | G12: 120000
C13: Personal Protective Equipment (PPE) | D13: 1 | E13: lot | F13: 30000 | G13: 30000
C14: Safety Signages and Barricades | D14: 1 | E14: lot | F14: 18000 | G14: 18000
C15: First Aid Kit and Emergency Kit | D15: 1 | E15: lot | F15: 15000 | G15: 15000
C16: Monthly Safety and Security Officer Fee | D16: 10 | E16: months | F16: 8700 | G16: 57000
B18: A.2 | C18: Material Testing | D18: =+I.2!C11 -> 1 | E18: =+I.2!E11 -> lot | F18: 55000 | G18: =+D18*F18 -> 55000
B20: A.3 | C20: Temporary Facilities | D20: 10 | E20: months | G20: 100000
C21: Contractor's Field Office | D21: 10 | E21: months | F21: 50000 | G21: -
C22: Temporary Water and Electricity | D22: 10 | E22: months | F22: 30000 | G22: -
C23: Toilet Facilities (portalets) | D23: 10 | E23: months | F23: 15000 | G23: -
C24: Material Stockpile Area | D24: 1 | E24: lot | F24: 5000 | G24: -
B26: A.4 | C26: Permits and Clearances | D26: 1 | E26: lot | G26: 95000
C27: Building Permit | D27: 1 | E27: lot | F27: 45000 | G27: -
C28: Electrical Permit | D28: 1 | E28: lot | F28: 20000 | G28: -
C29: Mechanical Permit | D29: 1 | E29: lot | F29: 15000 | G29: -
C30: Sanitary/Plumbing Permit | D30: 1 | E30: lot | F30: 15000 | G30: -
G31: -
B32: A.5 | C32: Project Close-out and Turnover | D32: 1 | E32: lot | F32: 25000 | G32: 25000
G33: -
C34: Site Works | G34: -
C35: Site Lay-out/Clearing & Grubbing | D35: 121 | E35: sq.m. | F35: 90 | G35: 10800
C36: Staking and Lay-out | D36: 1 | E36: lot | F36: 15000 | G36: =+D36*F36 -> 15000
C37: Excavation | D37: 105 | E37: =+II.3!E11 -> cu.m. | F37: 580 | G37: =+D37*F37 -> 60900
C38: Backfill & Compaction | D38: 85 | E38: =+II.4!E11 -> cu.m. | F38: 400 | G38: =+D38*F38 -> 34000
C39: Gravel Bedding | D39: 17 | E39: cu.m. | F39: 1700 | G39: =+D39*F39 -> 28900
C40: Temporary Fencing | D40: 50 | E40: lnm | F40: 1000 | G40: =+D40*F40 -> 50000
C42: Formworks & Scaffoldings (Rental) | D42: 10 | E42: =+III.!E9 -> months | F42: 40000 | G42: =+D42*F42 -> 400000
C43: Concrete Works | G43: -
C44: Fabrication of Reinforcing Bars for Footing, Columns & Beams | D44: 15.5 | E44: tons | F44: 56500 | G44: =+D44*F44 -> 875750
C45: Cast-in-place Concrete (3000 psi) for Footing, Columns & Beams | D45: 178 | E45: =+IV.2!E11 -> cu.m. | F45: 5600 | G45: =+D45*F45 -> 996800
C46: Plastering | D46: 1900 | E46: =+IV.3!E11 -> sq.m. | F46: 280 | G46: =+D46*F46 -> 532000
C47: Concrete Placement Labor | D47: 175 | E47: cu.m. | F47: 850 | G47: =+D47*F47 -> 148750
...

Sheet I.1
B3: Project Name: | C3: Proposed /Construction of Adidtional Footing/ Column & Beam for Archbishop's Palace
B4: Location: | C4: D. Jakosalem St., Cebu City
B6: Item No.: | C6: =+BOQ!B9 -> I.
B7: Item of Works: | C7: =+BOQ!C9 -> General Requirements
B8: Sub-Item No.: | C8: =+BOQ!B11 -> 0
B9: Sub-Item of Works: | C9: =+BOQ!C11 -> Project Billboard and Signages
B11: Quatity: | C11: 6 | D11: Unit: | E11: months
B14: Detailed Unit Price Analysis:
B15: A. MATERIALS
B16: DESCRIPTION | D16: QUANTITY | E16: UNIT | F16: UNIT COST | G16: AMOUNT
B18: Consumables includes Safety Gloves, Safety Googles, Harness, and other Protective & Safety Equipments) | D18: 8 | E18: =+E11 -> months | F18: 3000 | G18: =+D18*F18 -> 24000
B21: Total Materials Cost: | G21: =+SUM(G17:G20) -> 24000
B22: B. EQUIPMENT
B23: DESCRIPTION | D23: QTY | E23: RATE/DAY | F23: NO. OF DAYS | G23: AMOUNT
B24: Service Truck with Driver | D24: 1 | E24: 2000 | F24: 0 | G24: =+D24*E24*F24 -> 0
B27: Total Equipment Cost: | G27: =+SUM(G25:G26) -> 0
B28: C. MANPOWER
B29: DESCRIPTION | D29: QTY | E29: RATE/DAY | F29: NO. OF DAYS | G29: AMOUNT
B32: Total Manpower Cost: | G32: =+SUM(G24:G31) -> 0
B33: TOTAL DIRECT COST (A+B+C): | G33: =+SUM(G21,G27,G32) -> 24000
B35: D. Mobilization/Demobilization | E35: 0.01 | F35: of Direct Cost | G35: 0
B36: E. Overhead, Miscellaneous & Contingencies (OCM) | E36: 0.12 | F36: of Direct Cost | G36: 0
B37: F. Contractor's Profit | E37: 0.08 | F37: of Direct Cost | G37: 0
B38: G. VAT | E38: 0.05 | F38: of (DC+OCM+CP) | G38: =+E38*(G33+G36+G37) -> 1200
B39: TOTAL INDIRECT COST: | G39: =+SUM(G35:G38) -> 1200
B41: TOTAL CONSTRUCTION COST: | G41: =+SUM(G33,G39) -> 25200
B42: Unit Cost: | G42: =+G41/C11 -> 4200

Sheet I.2
B3: Project Name: | C3: Proposed /Construction of Adidtional Footing/ Column & Beam for Archbishop's Palace
B4: Location: | C4: D. Jakosalem St., Cebu City
B6: Item No.: | C6: =+BOQ!B34 -> 0
B7: Item of Works: | C7: =+BOQ!C34 -> Site Works
B8: Sub-Item No.: | C8: =+BOQ!B18 -> A.2
B9: Sub-Item of Works: | C9: =+BOQ!C18 -> Material Testing
B11: Quatity: | C11: 1 | D11: Unit: | E11: lot
B14: Detailed Unit Price Analysis:
B15: A. MATERIALS
B16: DESCRIPTION | D16: QUANTITY | E16: UNIT | F16: UNIT COST | G16: AMOUNT
B18: Material Testing | D18: =+C11 -> 1 | E18: =+E11 -> lot | F18: 10000 | G18: =+D18*F18 -> 10000
B21: Total Materials Cost: | G21: =+SUM(G17:G20) -> 10000
B22: B. EQUIPMENT
B23: DESCRIPTION | D23: QTY | E23: RATE/DAY | F23: NO. OF DAYS | G23: AMOUNT
B27: Total Equipment Cost: | G27: =+SUM(G25:G26) -> 0
B28: C. MANPOWER
B29: DESCRIPTION | D29: QTY | E29: RATE/DAY | F29: NO. OF DAYS | G29: AMOUNT
B31: Total Manpower Cost: | G31: =+SUM(G24:G30) -> 0
B32: TOTAL DIRECT COST (A+B+C): | G32: =+SUM(G21,G27,G31) -> 10000
B34: D. Mobilization/Demobilization | E34: 0.01 | F34: of Direct Cost | G34: 0
B35: E. Overhead, Miscellaneous & Contingencies (OCM) | E35: 0.12 | F35: of Direct Cost | G35: =+G32*E35 -> 1200
B36: F. Contractor's Profit | E36: 0.08 | F36: of Direct Cost | G36: =+G32*E36 -> 800
B37: G. VAT | E37: 0.05 | F37: of (DC+OCM+CP) | G37: =+E37*(G32+G35+G36) -> 600
B38: TOTAL INDIRECT COST: | G38: =+SUM(G34:G37) -> 2600
B40: TOTAL CONSTRUCTION COST: | G40: =+SUM(G32,G38) -> 12600
B41: Unit Cost: | G41: =+G40/C11 -> 12600

Sheet II.1
B3: Project Name: | C3: Proposed /Construction of Adidtional Footing/ Column & Beam for Archbishop's Palace
B4: Location: | C4: D. Jakosalem St., Cebu City
B6: Item No.: | C6: =+BOQ!B34 -> 0
B7: Item of Works: | C7: =+BOQ!C34 -> Site Works
B8: Sub-Item No.: | C8: =+BOQ!B35 -> 0
B9: Sub-Item of Works: | C9: =+BOQ!C35 -> Site Lay-out/Clearing & Grubbing
B11: Quatity: | C11: 1 | D11: Unit: | E11: lot
B14: Detailed Unit Price Analysis:
B15: A. MATERIALS
B16: DESCRIPTION | D16: QUANTITY | E16: UNIT | F16: UNIT COST | G16: AMOUNT
B21: Total Materials Cost: | G21: =+SUM(G17:G20) -> 0
B22: B. EQUIPMENT
B23: DESCRIPTION | D23: QTY | E23: RATE/DAY | F23: NO. OF DAYS | G23: AMOUNT
B24: Service Truck with Driver | D24: 1 | E24: 2000 | F24: 5 | G24: =+D24*E24*F24 -> 10000
B25: Minor Tools | D25: 2 | E25: 200 | F25: =+F24 -> 5 | G25: =+D25*E25*F25 -> 2000
B27: Total Equipment Cost: | G27: =+SUM(G25:G26) -> 2000
B28: C. MANPOWER
B29: DESCRIPTION | D29: QTY | E29: RATE/DAY | F29: NO. OF DAYS | G29: AMOUNT
B30: Unskilled Labor | D30: 4 | E30: 450 | F30: =+F25 -> 5 | G30: =+D30*E30*F30 -> 9000
B32: Total Manpower Cost: | G32: =+SUM(G24:G31) -> 23000
B33: TOTAL DIRECT COST (A+B+C): | G33: =+SUM(G21,G27,G32) -> 25000
B35: D. Mobilization/Demobilization | E35: 0.01 | F35: of Direct Cost | G35: =+G33*E35 -> 250
B36: E. Overhead, Miscellaneous & Contingencies (OCM) | E36: 0.12 | F36: of Direct Cost | G36: =+G33*E36 -> 3000
B37: F. Contractor's Profit | E37: 0.08 | F37: of Direct Cost | G37: =+G33*E37 -> 2000
B38: G. VAT | E38: 0.05 | F38: of (DC+OCM+CP) | G38: =+E38*(G33+G36+G37) -> 1500
B39: TOTAL INDIRECT COST: | G39: =+SUM(G35:G38) -> 6750
B41: TOTAL CONSTRUCTION COST: | G41: =+SUM(G33,G39) -> 31750
B42: Unit Cost: | G42: =+G41/C11 -> 31750

Sheet II.2
B3: Project Name: | C3: Proposed /Construction of Adidtional Footing/ Column & Beam for Archbishop's Palace
B4: Location: | C4: D. Jakosalem St., Cebu City
B6: Item No.: | C6: =+BOQ!B34 -> 0
B7: Item of Works: | C7: =+BOQ!C34 -> Site Works
B8: Sub-Item No.: | C8: =+BOQ!B36 -> 0
B9: Sub-Item of Works: | C9: =+BOQ!C36 -> Staking and Lay-out
B11: Quatity: | C11: =+J53 -> 91.9989 | D11: Unit: | E11: =+K53 -> sq.m.
B14: Detailed Unit Price Analysis:
B15: A. MATERIALS
B16: DESCRIPTION | D16: QUANTITY | E16: UNIT | F16: UNIT COST | G16: AMOUNT
B21: Total Materials Cost: | G21: =+SUM(G17:G20) -> 0
B22: B. EQUIPMENT
B23: DESCRIPTION | D23: QTY | E23: RATE/DAY | F23: NO. OF DAYS | G23: AMOUNT
B24: Jack Hammer | D24: 1 | E24: 2000 | F24: 7 | G24: =+D24*E24*F24 -> 14000 | H24: =+G46-H46 -> 0.0049916591
B25: Service Truck with Driver | D25: 1 | E25: 2000 | F25: =+F24 -> 7 | G25: =+D25*E25*F25 -> 14000 | H25: =+G45-I46 -> -0.36149385
B26: Chipping Gun | D26: 1 | E26: 500 | F26: =+F24 -> 7 | G26: =+D26*E26*F26 -> 3500
B27: Minor Tools | D27: 1 | E27: 200 | F27: =+F24 -> 7 | G27: =+D27*E27*F27 -> 1400
B29: Total Equipment Cost: | G29: =+SUM(G24:G28) -> 32900
B30: C. MANPOWER
B31: DESCRIPTION | D31: QTY | E31: RATE/DAY | F31: NO. OF DAYS | G31: AMOUNT
B32: Foreman | D32: 1 | E32: 750 | F32: 8.2935799 | G32: =+D32*E32*F32 -> 6220.1849
B33: Unskilled Labor | D33: 4 | E33: 450 | F33: =+F32 -> 8.2935799 | G33: =+D33*E33*F33 -> 14928.444
B36: Total Manpower Cost: | G36: =+SUM(G32:G35) -> 21148.629
B37: TOTAL DIRECT COST (A+B+C): | G37: =+SUM(G21,G29,G36) -> 54048.629
B39: D. Mobilization/Demobilization | E39: 0.01 | F39: of Direct Cost | G39: =+G37*E39 -> 540.48629
B40: E. Overhead, Miscellaneous & Contingencies (OCM) | E40: 0.12 | F40: of Direct Cost | G40: =+G37*E40 -> 6485.8354
B41: F. Contractor's Profit | E41: 0.08 | F41: of Direct Cost | G41: =+G37*E41 -> 4323.8903
B42: G. VAT | E42: 0.05 | F42: of (DC+OCM+CP) | G42: =+E42*(G37+G40+G41) -> 3242.9177
B43: TOTAL INDIRECT COST: | G43: =+SUM(G39:G42) -> 14593.13
B45: TOTAL CONSTRUCTION COST: | G45: =+SUM(G37,G43) -> 68641.759
B46: Unit Cost: | G46: =+G45/C11 -> 746.11499 | H46: 746.11 | I46: =+H46*92 -> 68642.12
B49: Detailed Quantity Calculations:
B50: Item No. | C50: Description | D50: No. of Units | E50: No. of Sets | F50: Length | G50: Width/Area | H50: Height | I50: %Waste | J50: Qty | K50: Unit
B52: =+C6 -> 0 | C52: =+C7 -> Site Works
B53: =+C8 -> 0 | C53: =+C9 -> Staking and Lay-out | J53: =+SUM(J54:J56) -> 91.9989 | K53: sq.m.
B54: a. | C54: Hallway | D54: 1 | E54: 2 | F54: =3.66+3.8+4.04+4 -> 15.5 | G54: 1.5 | H54: 1 | I54: 1.05 | J54: =+D54*E54*F54*G54*H54*I54 -> 48.825 | K54: sq.m.
B55: b. | C55: Columns | D55: 4 | E55: 10 | F55: 1.8 | G55: 1.8 | H55: 0.3 | I55: 1.05 | J55: =+D55*E55*F55*G55*H55*I55 -> 40.824 | K55: sq.m.
B56: c. | C56: Wall | D56: 1 | E56: 1 | F56: =3.66+3.8 -> 7.46 | G56: 1 | H56: 0.3 | I56: 1.05 | J56: =+D56*E56*F56*G56*H56*I56 -> 2.3499 | K56: sq.m.

Sheet II.3
B3: Project Name: | C3: Proposed /Construction of Adidtional Footing/ Column & Beam for Archbishop's Palace
B4: Location: | C4: D. Jakosalem St., Cebu City
B6: Item No.: | C6: =+BOQ!B34 -> 0
B7: Item of Works: | C7: =+BOQ!C34 -> Site Works
B8: Sub-Item No.: | C8: =+BOQ!B37 -> 0
B9: Sub-Item of Works: | C9: =+BOQ!C37 -> Excavation
B11: Quatity: | C11: =+J51 -> 173.2608 | D11: Unit: | E11: =+K51 -> cu.m.
B14: Detailed Unit Price Analysis:
B15: A. MATERIALS
B16: DESCRIPTION | D16: QUANTITY | E16: UNIT | F16: UNIT COST | G16: AMOUNT
B21: Total Materials Cost: | G21: =+SUM(G17:G20) -> 0
B22: B. EQUIPMENT
B23: DESCRIPTION | D23: QTY | E23: RATE/DAY | F23: NO. OF DAYS | G23: AMOUNT
B24: Service Truck with Driver | D24: 1 | E24: 2000 | F24: =+F30/3 -> 11.55072 | G24: =+D24*E24*F24 -> 23101.44
B25: Minor Tools | D25: 1 | E25: 200 | F25: =+F24 -> 11.55072 | G25: =+D25*E25*F25 -> 2310.144
B27: Total Equipment Cost: | G27: =+SUM(G24:G26) -> 25411.584
B28: C. MANPOWER
B29: DESCRIPTION | D29: QTY | E29: RATE/DAY | F29: NO. OF DAYS | G29: AMOUNT
B30: Foreman | D30: 1 | E30: 750 | F30: =+C11/(1*5) -> 34.65216 | G30: =+D30*E30*F30 -> 25989.12
B31: Unskilled Labor | D31: 5 | E31: 450 | F31: =+F30 -> 34.65216 | G31: =+D31*E31*F31 -> 77967.36
B34: Total Manpower Cost: | G34: =+SUM(G30:G33) -> 103956.48
B35: TOTAL DIRECT COST (A+B+C): | G35: =+SUM(G21,G27,G34) -> 129368.06
B37: D. Mobilization/Demobilization | E37: 0.01 | F37: of Direct Cost | G37: =+G35*E37 -> 1293.6806
B38: E. Overhead, Miscellaneous & Contingencies (OCM) | E38: 0.12 | F38: of Direct Cost | G38: =+G35*E38 -> 15524.168
B39: F. Contractor's Profit | E39: 0.08 | F39: of Direct Cost | G39: =+G35*E39 -> 10349.445
B40: G. VAT | E40: 0.05 | F40: of (DC+OCM+CP) | G40: =+E40*(G35+G38+G39) -> 7762.0838
B41: TOTAL INDIRECT COST: | G41: =+SUM(G37:G40) -> 34929.377
B43: TOTAL CONSTRUCTION COST: | G43: =+SUM(G35,G41) -> 164297.44
B44: Unit Cost: | G44: =+G43/C11 -> 948.26667
B47: Detailed Quantity Calculations:
B48: Item No. | C48: Description | D48: No. of Units | E48: No. of Sets | F48: Length | G48: Width/Area | H48: Height | I48: %Waste | J48: Qty | K48: Unit
B50: =+C6 -> 0 | C50: =+C7 -> Site Works
B51: =+C8 -> 0 | C51: =+C9 -> Excavation | J51: =+SUM(J52:J54) -> 173.2608 | K51: cu.m.
B52: a. | C52: Area Surrounded by Columns | D52: 8 | E52: 3 | F52: 1 | G52: =+(1.8*1.8)-(0.3*0.3) -> 3.15 | H52: 2 | I52: 1 | J52: =+D52*E52*F52*G52*H52*I52 -> 151.2 | K52: cu.m.
B53: b. | C53: Column | D53: 8 | E53: 2 | F53: 0.3 | G53: 0.3 | H53: 2 | I53: 1 | J53: =+D53*E53*F53*G53*H53*I53 -> 2.88 | K53: cu.m.
B54: c. | C54: Footing | D54: 8 | E54: 2 | F54: 1.8 | G54: 1.8 | H54: 0.37 | I54: 1 | J54: =+D54*E54*F54*G54*H54*I54 -> 19.1808 | K54: cu.m.

Sheet II.4
B3: Project Name: | C3: Proposed /Construction of Adidtional Footing/ Column & Beam for Archbishop's Palace
B4: Location: | C4: D. Jakosalem St., Cebu City
B6: Item No.: | C6: =+BOQ!B34 -> 0
B7: Item of Works: | C7: =+BOQ!C34 -> Site Works
B8: Sub-Item No.: | C8: =+BOQ!B38 -> 0
B9: Sub-Item of Works: | C9: =+BOQ!C38 -> Backfill & Compaction
B11: Quatity: | C11: =+J52 -> 170.3808 | D11: Unit: | E11: =+K52 -> cu.m.
B14: Detailed Unit Price Analysis:
B15: A. MATERIALS
B16: DESCRIPTION | D16: QUANTITY | E16: UNIT | F16: UNIT COST | G16: AMOUNT
B21: Total Materials Cost: | G21: =+SUM(G17:G20) -> 0
B22: B. EQUIPMENT
B23: DESCRIPTION | D23: QTY | E23: RATE/DAY | F23: NO. OF DAYS | G23: AMOUNT
B24: Service Truck with Driver | D24: 1 | E24: 2000 | F24: =+F31/3 -> 7.57248 | G24: =+D24*E24*F24 -> 15144.96
B25: Tampering Rammer/ Compactor | D25: 1 | E25: 1500 | F25: =+F24 -> 7.57248 | G25: =+D25*E25*F25 -> 11358.72
B26: Minor Tools | D26: 1 | E26: 200 | F26: =+F24 -> 7.57248 | G26: =+D26*E26*F26 -> 1514.496
B28: Total Equipment Cost: | G28: =+SUM(G24:G27) -> 28018.176
B29: C. MANPOWER
B30: DESCRIPTION | D30: QTY | E30: RATE/DAY | F30: NO. OF DAYS | G30: AMOUNT
B31: Foreman | D31: 1 | E31: 750 | F31: =+C11/(5*1.5) -> 22.71744 | G31: =+D31*E31*F31 -> 17038.08
B32: Unskilled Labor | D32: 5 | E32: 450 | F32: =+F31 -> 22.71744 | G32: =+D32*E32*F32 -> 51114.24
B35: Total Manpower Cost: | G35: =+SUM(G31:G34) -> 68152.32
B36: TOTAL DIRECT COST (A+B+C): | G36: =+SUM(G21,G28,G35) -> 96170.496
B38: D. Mobilization/Demobilization | E38: 0.01 | F38: of Direct Cost | G38: =+G36*E38 -> 961.70496
B39: E. Overhead, Miscellaneous & Contingencies (OCM) | E39: 0.12 | F39: of Direct Cost | G39: =+G36*E39 -> 11540.46
B40: F. Contractor's Profit | E40: 0.08 | F40: of Direct Cost | G40: =+G36*E40 -> 7693.6397
B41: G. VAT | E41: 0.05 | F41: of (DC+OCM+CP) | G41: =+E41*(G36+G39+G40) -> 5770.2298
B42: TOTAL INDIRECT COST: | G42: =+SUM(G38:G41) -> 25966.034
B44: TOTAL CONSTRUCTION COST: | G44: =+SUM(G36,G42) -> 122136.53
B45: Unit Cost: | G45: =+G44/C11 -> 716.84444
B48: Detailed Quantity Calculations:
B49: Item No. | C49: Description | D49: No. of Units | E49: No. of Sets | F49: Length | G49: Width/Area | H49: Height | I49: %Waste | J49: Qty | K49: Unit
B51: =+C6 -> 0 | C51: =+C7 -> Site Works
B52: =+C8 -> 0 | C52: =+C9 -> Backfill & Compaction | J52: =+SUM(J53:J54) -> 170.3808 | K52: cu.m.
B53: a. | C53: Area Surrounded by Columns | D53: 8 | E53: 3 | F53: 1 | G53: =+(1.8*1.8)-(0.3*0.3) -> 3.15 | H53: 2 | I53: 1 | J53: =+D53*E53*F53*G53*H53*I53 -> 151.2 | K53: cu.m.
B54: c. | C54: Footing | D54: 8 | E54: 2 | F54: 1.8 | G54: 1.8 | H54: 0.37 | I54: 1 | J54: =+D54*E54*F54*G54*H54*I54 -> 19.1808 | K54: cu.m.

Sheet III.
B3: Project Name: | C3: Proposed /Construction of Adidtional Footing/ Column & Beam for Archbishop's Palace
B4: Location: | C4: D. Jakosalem St., Cebu City
B6: Item No.: | C6: =+BOQ!B42 -> 0
B7: Item of Works: | C7: =+BOQ!C42 -> Formworks & Scaffoldings (Rental)
B9: Quatity: | C9: 6 | D9: Unit: | E9: months
B12: Detailed Unit Price Analysis:
B13: A. MATERIALS
B14: DESCRIPTION | D14: QUANTITY | E14: UNIT | F14: UNIT COST | G14: AMOUNT
B16: =+C7 -> Formworks & Scaffoldings (Rental) | D16: =+C9 -> 6 | E16: =+E9 -> months | F16: 15000 | G16: =+D16*F16 -> 90000
B19: Total Materials Cost: | G19: =+SUM(G15:G18) -> 90000
B20: B. EQUIPMENT
B21: DESCRIPTION | D21: QTY | E21: RATE/DAY | F21: NO. OF DAYS | G21: AMOUNT
B24: Total Equipment Cost: | G24: =+SUM(G22:G23) -> 0
B25: C. MANPOWER
B26: DESCRIPTION | D26: QTY | E26: RATE/DAY | F26: NO. OF DAYS | G26: AMOUNT
B29: Total Manpower Cost: | G29: =+SUM(G27:G28) -> 0
B30: TOTAL DIRECT COST (A+B+C): | G30: =+SUM(G19,G24,G29) -> 90000
B32: D. Mobilization/Demobilization | E32: 0.01 | F32: of Direct Cost | G32: 0
B33: E. Overhead, Miscellaneous & Contingencies (OCM) | E33: 0.12 | F33: of Direct Cost | G33: 0
B34: F. Contractor's Profit | E34: 0.08 | F34: of Direct Cost | G34: 0
B35: G. VAT | E35: 0.05 | F35: of (DC+OCM+CP) | G35: =+E35*(G30+G33+G34) -> 4500
B36: TOTAL INDIRECT COST: | G36: =+SUM(G32:G35) -> 4500
B38: TOTAL CONSTRUCTION COST: | G38: =+SUM(G30,G36) -> 94500
B39: Unit Cost: | G39: =+G38/C9 -> 15750

Sheet IV.1
B3: Project Name: | C3: Proposed /Construction of Adidtional Footing/ Column & Beam for Archbishop's Palace
B4: Location: | C4: D. Jakosalem St., Cebu City
B6: Item No.: | C6: =+BOQ!B43 -> 0
B7: Item of Works: | C7: =+BOQ!C43 -> Concrete Works
B8: Sub-Item No.: | C8: =+BOQ!B44 -> 0
B9: Sub-Item of Works: | C9: =+BOQ!C44 -> Fabrication of Reinforcing Bars for Footing, Columns & Beams
B11: Quatity: | C11: 1 | D11: Unit: | E11: lot
B14: Detailed Unit Price Analysis:
B15: A. MATERIALS
B16: DESCRIPTION | D16: QUANTITY | E16: UNIT | F16: UNIT COST | G16: AMOUNT
B17: 25mm dia Def Bars, Grade 40 | D17: 1 | E17: lumpsum | F17: 250000 | G17: =+D17*F17 -> 250000
B18: 20mm dia Def Bars, Grade 40 | D18: 1 | E18: lumpsum | F18: 250000 | G18: =+D18*F18 -> 250000
B19: 16mm dia Def Bars, Grade 40 | D19: 1 | E19: lumpsum | F19: 250000 | G19: =+D19*F19 -> 250000
B20: 12mm dia Def Bars, Grade 40 | D20: 1 | E20: lumpsum | F20: 250000 | G20: =+D20*F20 -> 250000
B21: 10mm dia Def Bars, Grade 33 | D21: 1 | E21: lumpsum | F21: 250000 | G21: =+D21*F21 -> 250000
B22: G.I. Tie Wire #16 | D22: 10 | E22: rolls | F22: 3000 | G22: =+D22*F22 -> 30000
B24: Total Materials Cost: | G24: =+SUM(G17:G23) -> 1280000
B25: B. EQUIPMENT
B26: DESCRIPTION | D26: QTY | E26: RATE/DAY | F26: NO. OF DAYS | G26: AMOUNT
B27: Service Truck with Driver | D27: 1 | E27: 2000 | F27: 2.500394 | G27: =+D27*E27*F27 -> 5000.788
B28: Bar Cutter | D28: 1 | E28: 500 | F28: 10 | G28: =+D28*E28*F28 -> 5000
B29: Bar Bender | D29: 1 | E29: 500 | F29: =+F28 -> 10 | G29: =+D29*E29*F29 -> 5000
B30: Minor Tools | D30: 2 | E30: 200 | F30: =+F28 -> 10 | G30: =+D30*E30*F30 -> 4000
B32: Total Equipment Cost: | G32: =+SUM(G27:G31) -> 19000.788
B33: C. MANPOWER
B34: DESCRIPTION | D34: QTY | E34: RATE/DAY | F34: NO. OF DAYS | G34: AMOUNT
B35: Foreman | D35: 1 | E35: 750 | F35: 22 | G35: =+D35*E35*F35 -> 16500
B36: Skilled Labor | D36: 10 | E36: 600 | F36: =+F35 -> 22 | G36: =+D36*E36*F36 -> 132000
B37: Unskilled Labor | D37: 10 | E37: 450 | F37: =+F36 -> 22 | G37: =+D37*E37*F37 -> 99000
B40: Total Manpower Cost: | G40: =+SUM(G35:G39) -> 247500
B41: TOTAL DIRECT COST (A+B+C): | G41: =+SUM(G24,G32,G40) -> 1546500.8
B43: D. Mobilization/Demobilization | E43: 0.01 | F43: of Direct Cost | G43: =+G41*E43 -> 15465.008
B44: E. Overhead, Miscellaneous & Contingencies (OCM) | E44: 0.12 | F44: of Direct Cost | G44: =+G41*E44 -> 185580.09
B45: F. Contractor's Profit | E45: 0.08 | F45: of Direct Cost | G45: =+G41*E45 -> 123720.06
B46: G. VAT | E46: 0.05 | F46: of (DC+OCM+CP) | G46: =+E46*(G41+G44+G45) -> 92790.047
B47: TOTAL INDIRECT COST: | G47: =+SUM(G43:G46) -> 417555.21 | L47: =+(500000*192)/28 -> 3428571.4
B49: TOTAL CONSTRUCTION COST: | G49: =+SUM(G41,G47) -> 1964056 | I49: 500000
B50: Unit Cost: | G50: =+G49/C11 -> 1964056 | I50: =+G50-I49 -> 1464056
B54: Detailed Quantity Calculations:
B55: Item No. | C55: Description | D55: No. of Units | E55: No. of Sets | F55: Length | G55: Width/Area | H55: Height/ Thickness | I55: %Waste | J55: Qty | K55: Unit
...

Sheet IV.2
B3: Project Name: | C3: Proposed /Construction of Adidtional Footing/ Column & Beam for Archbishop's Palace
B4: Location: | C4: D. Jakosalem St., Cebu City
B6: Item No.: | C6: =+BOQ!B43 -> 0
B7: Item of Works: | C7: =+BOQ!C43 -> Concrete Works
B8: Sub-Item No.: | C8: =+BOQ!B45 -> 0
B9: Sub-Item of Works: | C9: =+BOQ!C45 -> Cast-in-place Concrete (3000 psi) for Footing, Columns & Beams
B11: Quatity: | C11: =+J56 -> 187.64622 | D11: Unit: | E11: =+K56 -> cu.m.
B14: Detailed Unit Price Analysis:
B15: A. MATERIALS
B16: DESCRIPTION | D16: QUANTITY | E16: UNIT | F16: UNIT COST | G16: AMOUNT
B17: Portland Cement | D17: =+C11*12 -> 2251.7547 | E17: bags | F17: 290 | G17: =+D17*F17 -> 653008.86
B18: Sand | D18: =+ROUNDUP(C11*0.5,0) -> 94 | E18: cu.m. | F18: 2100 | G18: =+D18*F18 -> 197400
B19: Gravel | D19: =+ROUNDUP(C11,0) -> 188 | E19: cu.m. | F19: 2100 | G19: =+D19*F19 -> 394800
B20: Water | D20: =+C11*0.25 -> 46.911556 | E20: cu.m. | F20: 0 | G20: =+D20*F20 -> 0
B21: Consumables | D21: 1 | E21: lot | F21: 10000 | G21: =+D21*F21 -> 10000
B23: Total Materials Cost: | G23: =+SUM(G17:G22) -> 1255208.9
B24: B. EQUIPMENT
B25: DESCRIPTION | D25: QTY | E25: RATE/DAY | F25: NO. OF DAYS | G25: AMOUNT
B26: Service Truck with Driver | D26: 2 | E26: 2000 | F26: 18.4278 | G26: =+D26*E26*F26 -> 73711.2 | H26: =+G49-H49 -> 0.0024212286
B27: One Bagger Mixer | D27: 2 | E27: 1500 | F27: 35 | G27: =+D27*E27*F27 -> 105000
B28: Concrete Vibrator | D28: 2 | E28: 500 | F28: =+F27 -> 35 | G28: =+D28*E28*F28 -> 35000
B29: Minor Tools | D29: 2 | E29: 200 | F29: =+F27 -> 35 | G29: =+D29*E29*F29 -> 14000
B31: Total Equipment Cost: | G31: =+SUM(G26:G30) -> 227711.2
B32: C. MANPOWER
B33: DESCRIPTION | D33: QTY | E33: RATE/DAY | F33: NO. OF DAYS | G33: AMOUNT
B34: Foreman | D34: 1 | E34: 750 | F34: =+F27 -> 35 | G34: =+D34*E34*F34 -> 26250
B35: Skilled Labor | D35: 6 | E35: 600 | F35: =+F34 -> 35 | G35: =+D35*E35*F35 -> 126000
B36: Unskilled Labor | D36: 6 | E36: 450 | F36: =+F34 -> 35 | G36: =+D36*E36*F36 -> 94500
B39: Total Manpower Cost: | G39: =+SUM(G34:G38) -> 246750
B40: TOTAL DIRECT COST (A+B+C): | G40: =+SUM(G23,G31,G39) -> 1729670.1
B42: D. Mobilization/Demobilization | E42: 0.01 | F42: of Direct Cost | G42: =+G40*E42 -> 17296.701
B43: E. Overhead, Miscellaneous & Contingencies (OCM) | E43: 0.12 | F43: of Direct Cost | G43: =+G40*E43 -> 207560.41
B44: F. Contractor's Profit | E44: 0.08 | F44: of Direct Cost | G44: =+G40*E44 -> 138373.6
B45: G. VAT | E45: 0.05 | F45: of (DC+OCM+CP) | G45: =+E45*(G40+G43+G44) -> 103780.2
B46: TOTAL INDIRECT COST: | G46: =+SUM(G42:G45) -> 467010.92
B48: TOTAL CONSTRUCTION COST: | G48: =+SUM(G40,G46) -> 2196681
B49: Unit Cost: | G49: =+G48/C11 -> 11706.502 | H49: 11706.5
B52: Detailed Quantity Calculations:
B53: Item No. | C53: Description | D53: No. of Units | E53: No. of Sets | F53: Length | G53: Width/Area | H53: Height/ Thickness | I53: %Waste | J53: Qty | K53: Unit
B55: =+C6 -> 0 | C55: =+C7 -> Concrete Works
...

Sheet IV.3
B3: Project Name: | C3: Proposed /Construction of Adidtional Footing/ Column & Beam for Archbishop's Palace
B4: Location: | C4: D. Jakosalem St., Cebu City
B6: Item No.: | C6: =+BOQ!B43 -> 0
B7: Item of Works: | C7: =+BOQ!C43 -> Concrete Works
B8: Sub-Item No.: | C8: =+BOQ!B46 -> 0
B9: Sub-Item of Works: | C9: =+BOQ!C46 -> Plastering
B11: Quatity: | C11: =+J54 -> 208.9752 | D11: Unit: | E11: =+K54 -> sq.m.
B14: Detailed Unit Price Analysis:
B15: A. MATERIALS
B16: DESCRIPTION | D16: QUANTITY | E16: UNIT | F16: UNIT COST | G16: AMOUNT
B17: Cement | D17: =+ROUNDUP(J53*12,0) -> 251 | E17: bags | F17: 270 | G17: =+D17*F17 -> 67770
B18: Sand | D18: =+ROUNDUP(J53,0) -> 21 | E18: cu.m. | F18: 2100 | G18: =+D18*F18 -> 44100
B19: Water | D19: =+C11*0.25 -> 52.2438 | E19: cu.m. | F19: 0 | G19: =+D19*F19 -> 0
B20: Consumables | D20: 1 | E20: lot | F20: 2000 | G20: =+D20*F20 -> 2000
B22: Total Materials Cost: | G22: =+SUM(G17:G21) -> 113870
B23: B. EQUIPMENT
B24: DESCRIPTION | D24: QTY | E24: RATE/DAY | F24: NO. OF DAYS | G24: AMOUNT
B25: Service Truck with Driver | D25: 1 | E25: 2000 | F25: 4.585 | G25: =+D25*E25*F25 -> 9170 | H25: =+G46-H46 -> 0.004879067
B26: Minor Tools | D26: 2 | E26: 200 | F26: 2 | G26: =+D26*E26*F26 -> 800
B28: Total Equipment Cost: | G28: =+SUM(G25:G27) -> 9970
B29: C. MANPOWER
B30: DESCRIPTION | D30: QTY | E30: RATE/DAY | F30: NO. OF DAYS | G30: AMOUNT
B31: Foreman | D31: 1 | E31: 750 | F31: =+C11/12 -> 17.4146 | G31: =+D31*E31*F31 -> 13060.95
B32: Skilled Labor | D32: 4 | E32: 600 | F32: =+F31 -> 17.4146 | G32: =+D32*E32*F32 -> 41795.04
B33: Unskilled Labor | D33: 4 | E33: 450 | F33: =+F31 -> 17.4146 | G33: =+D33*E33*F33 -> 31346.28
B36: Total Manpower Cost: | G36: =+SUM(G31:G35) -> 86202.27
B37: TOTAL DIRECT COST (A+B+C): | G37: =+SUM(G22,G28,G36) -> 210042.27
B39: D. Mobilization/Demobilization | E39: 0.01 | F39: of Direct Cost | G39: =+G37*E39 -> 2100.4227
B40: E. Overhead, Miscellaneous & Contingencies (OCM) | E40: 0.12 | F40: of Direct Cost | G40: =+G37*E40 -> 25205.072
B41: F. Contractor's Profit | E41: 0.08 | F41: of Direct Cost | G41: =+G37*E41 -> 16803.382
B42: G. VAT | E42: 0.05 | F42: of (DC+OCM+CP) | G42: =+E42*(G37+G40+G41) -> 12602.536
B43: TOTAL INDIRECT COST: | G43: =+SUM(G39:G42) -> 56711.413
B45: TOTAL CONSTRUCTION COST: | G45: =+SUM(G37,G43) -> 266753.68
B46: Unit Cost: | G46: =+G45/C11 -> 1276.4849 | H46: 1276.48
B49: Detailed Quantity Calculations:
B50: Item No. | C50: Description | D50: No. of Units | E50: No. of Sets | F50: Length | G50: Width/Area | H50: Height | I50: %Waste | J50: Qty | K50: Unit
B52: =+C6 -> 0 | C52: =+C7 -> Concrete Works
B53: =+C8 -> 0 | C53: =+C9 -> Plastering | I53: volume | J53: =+J54*0.1 -> 20.89752 | K53: cu.m.
J54: =+SUM(J55:J68) -> 208.9752 | K54: sq.m.
B55: a. | C55: Column | D55: =8 -> 8 | E55: =4*2 -> 8 | F55: 0.3 | G55: 1 | H55: 3 | I55: 1.05 | J55: =+D55*E55*F55*G55*H55*I55 -> 60.48 | K55: sq.m.
...

Sheet V.1
B3: Project Name: | C3: Proposed /Construction of Adidtional Footing/ Column & Beam for Archbishop's Palace
B4: Location: | C4: D. Jakosalem St., Cebu City
B6: Item No.: | C6: =+BOQ!B68 -> 0
B7: Item of Works: | C7: =+BOQ!C68 -> Architectural Works
B8: Sub-Item No.: | C8: =+BOQ!B70 -> 0
B9: Sub-Item of Works: | C9: =+BOQ!C70 -> Homogenous Tiles 600x600mm/units
B11: Quatity: | C11: =+J55 -> 203.6475 | D11: Unit: | E11: =+K55 -> sq.m.
B14: Detailed Unit Price Analysis:
B15: A. MATERIALS
B16: DESCRIPTION | D16: QUANTITY | E16: UNIT | F16: UNIT COST | G16: AMOUNT
B17: 6" CHB | D17: =+ROUNDUP(J55/(0.2032*0.4064),0) -> 2467 | E17: pcs | F17: 25 | G17: =+D17*F17 -> 61675
B18: Cement | D18: =+ROUNDUP(J67*12*1.05,0) -> 115 | E18: bags | F18: 270 | G18: =+D18*F18 -> 31050
B19: Sand | D19: =+ROUNDUP(J67*1.03,0) -> 10 | E19: cu.m. | F19: 2100 | G19: =+D19*F19 -> 21000
B20: Water | D20: =+J67*0.25 -> 2.2797653 | E20: cu.m. | F20: 0 | G20: =+D20*F20 -> 0
B22: Consumables | D22: 1 | E22: lot | F22: 2000 | G22: =+D22*F22 -> 2000
B24: Total Materials Cost: | G24: =+SUM(G18:G23) -> 54050
B25: B. EQUIPMENT
B26: DESCRIPTION | D26: QTY | E26: RATE/DAY | F26: NO. OF DAYS | G26: AMOUNT
B27: Service Truck with Driver | D27: 1 | E27: 2000 | F27: 1 | G27: =+D27*E27*F27 -> 2000
B28: Minor Tools | D28: 4 | E28: 200 | F28: 4 | G28: =+D28*E28*F28 -> 3200
B30: Total Equipment Cost: | G30: =+SUM(G27:G29) -> 5200
B31: C. MANPOWER
B32: DESCRIPTION | D32: QTY | E32: RATE/DAY | F32: NO. OF DAYS | G32: AMOUNT
B33: Foreman | D33: 1 | E33: 750 | F33: =+C11/8 -> 25.455938 | G33: =+D33*E33*F33 -> 19091.953
B34: Skilled Labor | D34: 4 | E34: 600 | F34: =+F33 -> 25.455938 | G34: =+D34*E34*F34 -> 61094.25
B35: Unskilled Labor | D35: 4 | E35: 450 | F35: =+F33 -> 25.455938 | G35: =+D35*E35*F35 -> 45820.688
B38: Total Manpower Cost: | G38: =+SUM(G33:G37) -> 126006.89
B39: TOTAL DIRECT COST (A+B+C): | G39: =+SUM(G24,G30,G38) -> 185256.89
B41: D. Mobilization/Demobilization | E41: 0.01 | F41: of Direct Cost | G41: =+G39*E41 -> 1852.5689
B42: E. Overhead, Miscellaneous & Contingencies (OCM) | E42: 0.12 | F42: of Direct Cost | G42: =+G39*E42 -> 22230.827
B43: F. Contractor's Profit | E43: 0.08 | F43: of Direct Cost | G43: =+G39*E43 -> 14820.551
B44: G. VAT | E44: 0.05 | F44: of (DC+OCM+CP) | G44: =+E44*(G39+G42+G43) -> 11115.413
B45: TOTAL INDIRECT COST: | G45: =+SUM(G41:G44) -> 50019.36
B47: TOTAL CONSTRUCTION COST: | G47: =+SUM(G39,G45) -> 235276.25
B48: Unit Cost: | G48: =+G47/C11 -> 1155.3113
B51: Detailed Quantity Calculations:
B52: Item No. | C52: Description | D52: No. of Units | E52: No. of Sets | F52: Length | G52: Width/Area | H52: Height | I52: %Waste | J52: Qty | K52: Unit
B54: =+C6 -> 0 | C54: =+C7 -> Architectural Works
B55: =+C8 -> 0 | C55: =+C9 -> Homogenous Tiles 600x600mm/units | D55: Size of 6" CHB | E55: (6"x8"x16") | F55: (152.4mmx203.2mmx406.4mm) | J55: =+SUM(J56:J58) -> 203.6475 | K55: sq.m.
C56: Gym Exterior along Grid 1 | D56: 1 | E56: 3 | F56: 6.5 | G56: 1 | H56: 3 | I56: 1.05 | J56: =+D56*E56*F56*G56*H56*I56 -> 61.425 | K56: sq.m.
...

Sheet V.2
B3: Project Name: | C3: Proposed /Construction of Adidtional Footing/ Column & Beam for Archbishop's Palace
B4: Location: | C4: D. Jakosalem St., Cebu City
B6: Item No.: | C6: =+BOQ!B68 -> 0
B7: Item of Works: | C7: =+BOQ!C68 -> Architectural Works
B8: Sub-Item No.: | C8: =+BOQ!B71 -> 0
B9: Sub-Item of Works: | C9: =+BOQ!C71 -> Non-slip Tiles Roofdeck and Bath
B11: Quatity: | C11: =+J56 -> 269.325 | D11: Unit: | E11: =+K56 -> sq.m.
B14: Detailed Unit Price Analysis:
B15: A. MATERIALS
B16: DESCRIPTION | D16: QUANTITY | E16: UNIT | F16: UNIT COST | G16: AMOUNT
B17: 6" CHB | D17: =+ROUNDUP(J56/(0.2032*0.4064),0) -> 3262 | E17: pcs | F17: 25 | G17: =+D17*F17 -> 81550
B18: Mortar in Between CHB Lines:
B19: Cement | D19: =+ROUNDUP(J64*12*1.05,0) -> 145 | E19: bags | F19: 290 | G19: =+D19*F19 -> 42050
B20: Sand | D20: =+ROUNDUP(J64*1.03,0) -> 12 | E20: cu.m. | F20: 2100 | G20: =+D20*F20 -> 25200
B21: Water | D21: =+J64*0.25 -> 2.86306 | E21: cu.m. | F21: 0 | G21: =+D21*F21 -> 0
B23: Consumables | D23: 1 | E23: lot | F23: 2000 | G23: =+D23*F23 -> 2000
B25: Total Materials Cost: | G25: =+SUM(G19:G24) -> 69250
B26: B. EQUIPMENT
B27: DESCRIPTION | D27: QTY | E27: RATE/DAY | F27: NO. OF DAYS | G27: AMOUNT
B28: Service Truck with Driver | D28: 1 | E28: 2000 | F28: 1 | G28: =+D28*E28*F28 -> 2000
B29: Minor Tools | D29: 2 | E29: 200 | F29: 1.93 | G29: =+D29*E29*F29 -> 772
B31: Total Equipment Cost: | G31: =+SUM(G28:G30) -> 2772
B32: C. MANPOWER
B33: DESCRIPTION | D33: QTY | E33: RATE/DAY | F33: NO. OF DAYS | G33: AMOUNT
B34: Foreman | D34: 1 | E34: 750 | F34: =+C11/9.5 -> 28.35 | G34: =+D34*E34*F34 -> 21262.5
B35: Skilled Labor | D35: 4 | E35: 600 | F35: =+F34 -> 28.35 | G35: =+D35*E35*F35 -> 68040
B36: Unskilled Labor | D36: 4 | E36: 450 | F36: =+F34 -> 28.35 | G36: =+D36*E36*F36 -> 51030
B39: Total Manpower Cost: | G39: =+SUM(G34:G38) -> 140332.5
B40: TOTAL DIRECT COST (A+B+C): | G40: =+SUM(G25,G31,G39) -> 212354.5
B42: D. Mobilization/Demobilization | E42: 0.01 | F42: of Direct Cost | G42: =+G40*E42 -> 2123.545
B43: E. Overhead, Miscellaneous & Contingencies (OCM) | E43: 0.12 | F43: of Direct Cost | G43: =+G40*E43 -> 25482.54
B44: F. Contractor's Profit | E44: 0.08 | F44: of Direct Cost | G44: =+G40*E44 -> 16988.36
B45: G. VAT | E45: 0.05 | F45: of (DC+OCM+CP) | G45: =+E45*(G40+G43+G44) -> 12741.27
B46: TOTAL INDIRECT COST: | G46: =+SUM(G42:G45) -> 57335.715
B48: TOTAL CONSTRUCTION COST: | G48: =+SUM(G40,G46) -> 269690.22
B49: Unit Cost: | G49: =+G48/C11 -> 1001.356 | H49: =+V.1!G48 -> 1155.3113 | I49: =+G49-H49 -> -153.95523
B52: Detailed Quantity Calculations:
B53: Item No. | C53: Description | D53: No. of Units | E53: No. of Sets | F53: Length | G53: Width/Area | H53: Height | I53: %Waste | J53: Qty | K53: Unit
B55: =+C6 -> 0 | C55: =+C7 -> Architectural Works
B56: =+C8 -> 0 | C56: =+C9 -> Non-slip Tiles Roofdeck and Bath | D56: Size of 6" CHB | E56: (6"x8"x16") | F56: (152.4mmx203.2mmx406.4mm) | J56: =+SUM(J57:J57) -> 269.325 | K56: sq.m.
...

Sheet VI.
B3: Project Name: | C3: Proposed /Construction of Adidtional Footing/ Column & Beam for Archbishop's Palace
B4: Location: | C4: D. Jakosalem St., Cebu City
B6: Item No.: | C6: =+BOQ!B74 -> 0
B7: Item of Works: | C7: =+BOQ!C74 -> Ceiling Works
B9: Quatity: | C9: =+J55 -> 202.923 | D9: Unit: | E9: =+K55 -> sq.m.
B12: Detailed Unit Price Analysis:
B13: A. MATERIALS
B14: DESCRIPTION | D14: QUANTITY | E14: UNIT | F14: UNIT COST | G14: AMOUNT
B15: 9mm Thick Gypsum Board | D15: 77 | E15: sheets | F15: 386 | G15: =+D15*F15 -> 29722
B16: Gypsum Putty | D16: 13 | E16: gals | F16: =+ROUNDUP(210*1.2,0) -> 252 | G16: =+D16*F16 -> 3276
B17: Mesh Tape | D17: 20 | E17: roll | F17: =+ROUNDUP(60*1.2,0) -> 72 | G17: =+D17*F17 -> 1440
B18: Gyspsum Screw | D18: 5200 | E18: pcs | F18: =+ROUNDUP(2.5*1.2,0) -> 3 | G18: =+D18*F18 -> 15600
B19: Alpha Main Bar | D19: 1680 | E19: ln.m. | F19: =+ROUNDUP(20*1.2,0) -> 24 | G19: =+D19*F19 -> 40320
B20: Cross Tee, 4ft | D20: 948 | E20: ln.m. | F20: =+ROUNDUP(20*1.2,0) -> 24 | G20: =+D20*F20 -> 22752
B21: Main Tee, 12 ft | D21: 804.06 | E21: ln.m. | F21: =+ROUNDUP(30*1.2,0) -> 36 | G21: =+D21*F21 -> 28946.16
B22: Wall Angle, 10 ft | D22: 20 | E22: lengths | F22: =+ROUNDUP(50*1.2,0) -> 60 | G22: =+D22*F22 -> 1200
B23: Hangers | D23: 561 | E23: lengths | F23: =+ROUNDUP(25*1.2,0) -> 30 | G23: =+D23*F23 -> 16830
B25: Total Materials Cost: | G25: =+SUM(G15:G24) -> 160086.16
B26: B. EQUIPMENT
B27: DESCRIPTION | D27: QTY | E27: RATE/DAY | F27: NO. OF DAYS | G27: AMOUNT
B28: Service Truck with Driver | D28: 1 | E28: 2000 | F28: 3.2286 | G28: =+D28*E28*F28 -> 6457.2 | H28: =+G49-H49 -> 0.00014429118
B29: Minor Tools | D29: 4 | E29: 200 | F29: 4 | G29: =+D29*E29*F29 -> 3200
B31: Total Equipment Cost: | G31: =+SUM(G28:G30) -> 9657.2
B32: C. MANPOWER
B33: DESCRIPTION | D33: QTY | E33: RATE/DAY | F33: NO. OF DAYS | G33: AMOUNT
B34: Foreman | D34: 1 | E34: 750 | F34: 15 | G34: =+D34*E34*F34 -> 11250
B35: Skilled Labor | D35: 4 | E35: 600 | F35: =+F34 -> 15 | G35: =+D35*E35*F35 -> 36000
B36: Unskilled Labor | D36: 4 | E36: 450 | F36: =+F34 -> 15 | G36: =+D36*E36*F36 -> 27000
B39: Total Manpower Cost: | G39: =+SUM(G34:G38) -> 74250
B40: TOTAL DIRECT COST (A+B+C): | G40: =+SUM(G25,G31,G39) -> 243993.36
B42: D. Mobilization/Demobilization | E42: 0.01 | F42: of Direct Cost | G42: =+G40*E42 -> 2439.9336
B43: E. Overhead, Miscellaneous & Contingencies (OCM) | E43: 0.12 | F43: of Direct Cost | G43: =+G40*E43 -> 29279.203
B44: F. Contractor's Profit | E44: 0.08 | F44: of Direct Cost | G44: =+G40*E44 -> 19519.469
B45: G. VAT | E45: 0.05 | F45: of (DC+OCM+CP) | G45: =+E45*(G40+G43+G44) -> 14639.602
B46: TOTAL INDIRECT COST: | G46: =+SUM(G42:G45) -> 65878.207
B48: TOTAL CONSTRUCTION COST: | G48: =+SUM(G40,G46) -> 309871.57
B49: Unit Cost: | G49: =+G48/C9 -> 1527.0401 | H49: 1527.04
B52: Detailed Quantity Calculations:
B53: Item No. | C53: Description | D53: No. of Units | E53: No. of Sets | F53: Length | G53: Width/Area | H53: Height | I53: %Waste | J53: Qty | K53: Unit
B55: =+C6 -> 0 | C55: =+C7 -> Ceiling Works | J55: =+SUM(J56:J57) -> 202.923 | K55: sq.m.
...

Sheet VII.1
B3: Project Name: | C3: Proposed /Construction of Adidtional Footing/ Column & Beam for Archbishop's Palace
B4: Location: | C4: D. Jakosalem St., Cebu City
B6: Item No.: | C6: =+BOQ!B78 -> 0
B7: Item of Works: | C7: =+BOQ!C78 -> Window Works (Jalousie Type)
B8: Sub-Item No.: | C8: =+BOQ!B81 -> 0
B9: Sub-Item of Works: | C9: =+BOQ!C81 -> Installation Labor
B11: Quatity: | C11: =+J55 -> 219.605 | D11: Unit: | E11: =+K55 -> ln.m.
B14: Detailed Unit Price Analysis:
B15: A. MATERIALS
B16: DESCRIPTION | D16: QUANTITY | E16: UNIT | F16: UNIT COST | G16: AMOUNT
B17: 50mmx50mmx6mm Angle Bar | D17: =+ROUNDUP(SUM(J56,J65)/6,0) -> 14 | E17: lengths | F17: =ROUNDUP(1292*1.1,0) -> 1422 | G17: =+D17*F17 -> 19908
B18: 50mmx75mmx1.2mm C-purlins | D18: =+ROUNDUP(J75/6,0) -> 24 | E18: lengths | F18: =ROUNDUP(499*1.1,0) -> 549 | G18: =+D18*F18 -> 13176
B19: Welding Rod #6011 | D19: 7 | E19: box | F19: 2700 | G19: =+D19*F19 -> 18900
B20: Consumables | D20: 1 | E20: lot | F20: 2500 | G20: =+D20*F20 -> 2500
B22: Total Materials Cost: | G22: =+SUM(G17:G21) -> 54484
B23: B. EQUIPMENT
B24: DESCRIPTION | D24: QTY | E24: RATE/DAY | F24: NO. OF DAYS | G24: AMOUNT
B25: Service Truck with Driver | D25: 1 | E25: 2000 | F25: 0 | G25: =+D25*E25*F25 -> 0
B26: Welding Machine | D26: 2 | E26: 1500 | F26: =7 -> 7 | G26: =+D26*E26*F26 -> 21000
B27: Cutting Otfit | D27: 1 | E27: 800 | F27: =+F33-F26 -> 5 | G27: =+D27*E27*F27 -> 4000
B28: Minor Tools | D28: 4 | E28: 200 | F28: 4 | G28: =+D28*E28*F28 -> 3200
B30: Total Equipment Cost: | G30: =+SUM(G25:G29) -> 28200
B31: C. MANPOWER
B32: DESCRIPTION | D32: QTY | E32: RATE/DAY | F32: NO. OF DAYS | G32: AMOUNT
B33: Foreman | D33: 1 | E33: 750 | F33: 12 | G33: =+D33*E33*F33 -> 9000
B34: Skilled Labor | D34: 4 | E34: 600 | F34: =+F33 -> 12 | G34: =+D34*E34*F34 -> 28800
B35: Unskilled Labor | D35: 4 | E35: 450 | F35: =+F33 -> 12 | G35: =+D35*E35*F35 -> 21600
B38: Total Manpower Cost: | G38: =+SUM(G33:G37) -> 59400
B39: TOTAL DIRECT COST (A+B+C): | G39: =+SUM(G22,G30,G38) -> 142084
B41: D. Mobilization/Demobilization | E41: 0.01 | F41: of Direct Cost | G41: =+G39*E41 -> 1420.84
B42: E. Overhead, Miscellaneous & Contingencies (OCM) | E42: 0.12 | F42: of Direct Cost | G42: =+G39*E42 -> 17050.08
B43: F. Contractor's Profit | E43: 0.08 | F43: of Direct Cost | G43: =+G39*E43 -> 11366.72
B44: G. VAT | E44: 0.05 | F44: of (DC+OCM+CP) | G44: =+E44*(G39+G42+G43) -> 8525.04
B45: TOTAL INDIRECT COST: | G45: =+SUM(G41:G44) -> 38362.68
B47: TOTAL CONSTRUCTION COST: | G47: =+SUM(G39,G45) -> 180446.68
B48: Unit Cost: | G48: =+G47/C11 -> 821.68748
B51: Detailed Quantity Calculations:
B52: Item No. | C52: Description | D52: No. of Units | E52: No. of Sets | F52: Length | G52: Width/Area | H52: Height | I52: %Waste | J52: Qty | K52: Unit
B54: =+C6 -> 0 | C54: =+C7 -> Window Works (Jalousie Type)
B55: =+C8 -> 0 | C55: =+C9 -> Installation Labor | J55: =+SUM(J56,J65,J75) -> 219.605 | K55: ln.m.
...

Sheet VII.2
B3: Project Name: | C3: Proposed /Construction of Adidtional Footing/ Column & Beam for Archbishop's Palace
B4: Location: | C4: D. Jakosalem St., Cebu City
B6: Item No.: | C6: =+BOQ!B78 -> 0
B7: Item of Works: | C7: =+BOQ!C78 -> Window Works (Jalousie Type)
B8: Sub-Item No.: | C8: =+BOQ!B82 -> 0
B9: Sub-Item of Works: | C9: =+BOQ!C82 -> Doors
B11: Quatity: | C11: =+J54 -> 199.21671 | D11: Unit: | E11: =+K54 -> sq.m.
B14: Detailed Unit Price Analysis:
B15: A. MATERIALS
B16: DESCRIPTION | D16: QUANTITY | E16: UNIT | F16: UNIT COST | G16: AMOUNT
B17: Corrugated G.I. Sheet x 10ft, Guage 22 | D17: =+ROUNDUP(J56/0.8,0) -> 40 | E17: sheets | F17: 1150 | G17: =+D17*F17 -> 46000
B18: Corrugated G.I. Sheet x 12ft, Guage 22 | D18: =+ROUNDUP(J57/0.8,0) -> 40 | E18: sheets | F18: =1150*1.1 -> 1265 | G18: =+D18*F18 -> 50600
B19: TeckScrew | D19: 2000 | E19: pcs | F19: 3 | G19: =+D19*F19 -> 6000
B20: Fascia Board | D20: =+ROUNDUP(J58/3,0) -> 15 | E20: lengths | F20: 485 | G20: =+D20*F20 -> 7275
B21: Consumables | D21: 1 | E21: lot | F21: 6000 | G21: =+D21*F21 -> 6000
B23: Total Materials Cost: | G23: =+SUM(G17:G22) -> 115875
B24: B. EQUIPMENT
B25: DESCRIPTION | D25: QTY | E25: RATE/DAY | F25: NO. OF DAYS | G25: AMOUNT
B26: Service Truck with Driver | D26: 1 | E26: 2000 | F26: 2 | G26: =+D26*E26*F26 -> 4000 | H26: =+G47-H47 -> 0.002243238
B27: Minor Tools | D27: 2 | E27: 200 | F27: 5 | G27: =+D27*E27*F27 -> 2000
B29: Total Equipment Cost: | G29: =+SUM(G26:G28) -> 6000
B30: C. MANPOWER
B31: DESCRIPTION | D31: QTY | E31: RATE/DAY | F31: NO. OF DAYS | G31: AMOUNT
B32: Foreman | D32: 1 | E32: 750 | F32: 14.4446 | G32: =+D32*E32*F32 -> 10833.45
B33: Skilled Labor | D33: 5 | E33: 600 | F33: =+F32 -> 14.4446 | G33: =+D33*E33*F33 -> 43333.8
B34: Unskilled Labor | D34: 5 | E34: 450 | F34: =+F32 -> 14.4446 | G34: =+D34*E34*F34 -> 32500.35
B37: Total Manpower Cost: | G37: =+SUM(G32:G36) -> 86667.6
B38: TOTAL DIRECT COST (A+B+C): | G38: =+SUM(G23,G29,G37) -> 208542.6
B40: D. Mobilization/Demobilization | E40: 0.01 | F40: of Direct Cost | G40: =+G38*E40 -> 2085.426
B41: E. Overhead, Miscellaneous & Contingencies (OCM) | E41: 0.12 | F41: of Direct Cost | G41: =+G38*E41 -> 25025.112
B42: F. Contractor's Profit | E42: 0.08 | F42: of Direct Cost | G42: =+G38*E42 -> 16683.408
B43: G. VAT | E43: 0.05 | F43: of (DC+OCM+CP) | G43: =+E43*(G38+G41+G42) -> 12512.556
B44: TOTAL INDIRECT COST: | G44: =+SUM(G40:G43) -> 56306.502
B46: TOTAL CONSTRUCTION COST: | G46: =+SUM(G38,G44) -> 264849.1
B47: Unit Cost: | G47: =+G46/C11 -> 1329.4522 | H47: 1329.45
B50: Detailed Quantity Calculations:
B51: Item No. | C51: Description | D51: No. of Units | E51: No. of Sets | F51: Length | G51: Width/Area | H51: Height | I51: %Waste | J51: Qty | K51: Unit
B53: =+C6 -> 0 | C53: =+C7 -> Window Works (Jalousie Type)
B54: =+C8 -> 0 | C54: =+C9 -> Doors | D54: 2 | E54: 1 | F54: =14.63+0.5 -> 15.13 | G54: =+(4.34+0.5+0.5+4.2+1.5+1.5)/2 -> 6.27 | H54: 1 | I54: 1.05 | J54: =+D54*E54*F54*G54*H54*I54 -> 199.21671 | K54: sq.m.
C56: Corrugated G.I. Sheet x 10ft, Guage 22 | D56: 2 | E56: 1 | F56: =14.63+0.5 -> 15.13 | G56: 1 | H56: 1 | I56: 1.05 | J56: =+D56*E56*F56*G56*H56*I56 -> 31.773 | K56: ln.m.
...

Sheet VIII.
B3: Project Name: | C3: Proposed /Construction of Adidtional Footing/ Column & Beam for Archbishop's Palace
B4: Location: | C4: D. Jakosalem St., Cebu City
B6: Item No.: | C6: =+BOQ!B88 -> 0
B7: Item of Works: | C7: =+BOQ!C88 -> Painting Works
B9: Quatity: | C9: 1 | D9: Unit: | E9: lot
B12: Detailed Unit Price Analysis:
B13: A. MATERIALS
B14: DESCRIPTION | D14: QUANTITY | E14: UNIT | F14: UNIT COST | G14: AMOUNT
B17: Painting (Interior & Exterior Walls) | D17: 1 | E17: lot | F17: 300000 | G17: =+D17*F17 -> 300000
B22: Total Materials Cost: | G22: =+SUM(G15:G20) -> 300000
B23: B. EQUIPMENT
B24: DESCRIPTION | D24: QTY | E24: RATE/DAY | F24: NO. OF DAYS | G24: AMOUNT
B28: Total Equipment Cost: | G28: =+SUM(G25:G27) -> 0
B29: C. MANPOWER
B30: DESCRIPTION | D30: QTY | E30: RATE/DAY | F30: NO. OF DAYS | G30: AMOUNT
B36: Total Manpower Cost: | G36: =+SUM(G31:G35) -> 0
B37: TOTAL DIRECT COST (A+B+C): | G37: =+SUM(G22,G28,G36) -> 300000
B39: D. Mobilization/Demobilization | E39: 0.01 | F39: of Direct Cost | G39: =+G37*E39 -> 3000
B40: E. Overhead, Miscellaneous & Contingencies (OCM) | E40: 0.12 | F40: of Direct Cost | G40: =+G37*E40 -> 36000
B41: F. Contractor's Profit | E41: 0.08 | F41: of Direct Cost | G41: =+G37*E41 -> 24000
B42: G. VAT | E42: 0.05 | F42: of (DC+OCM+CP) | G42: =+E42*(G37+G40+G41) -> 18000
B43: TOTAL INDIRECT COST: | G43: =+SUM(G39:G42) -> 81000
B45: TOTAL CONSTRUCTION COST: | G45: =+SUM(G37,G43) -> 381000
B46: Unit Cost: | G46: =+G45/C9 -> 381000
B49: Detailed Quantity Calculations:
B50: Item No. | C50: Description | D50: No. of Units | E50: No. of Sets | F50: Length | G50: Width/Area | H50: Height | I50: %Waste | J50: Qty | K50: Unit
B52: =+C6 -> 0 | C52: =+C7 -> Painting Works
J53: =+SUM(J57:J73) -> 420.0252 | K53: sq.m.
B54: a. | C54: Column | D54: 8 | E54: 8 | F54: 0.3 | G54: 1 | H54: 3 | I54: 1.05 | J54: =+D54*E54*F54*G54*H54*I54 -> 60.48 | K54: sq.m.
B55: b. | C55: Beams
B56: b.1 | C56: 2B1
C57: Grid 2- F to G | D57: 1 | E57: 8 | F57: 0.25 | G57: 1 | H57: 6.5 | I57: 1.05 | J57: =+D57*E57*F57*G57*H57*I57 -> 13.65 | K57: sq.m.
C58: Grid E-F | D58: 2 | E58: 8 | F58: 0.3 | G58: 1 | H58: 4.02 | I58: 1.05 | J58: =+D58*E58*F58*G58*H58*I58 -> 20.2608 | K58: sq.m.
C59: Grid F-G | D59: 2 | E59: 8 | F59: 0.3 | G59: 1 | H59: 4.11 | I59: 1.05 | J59: =+D59*E59*F59*G59*H59*I59 -> 20.7144 | K59: sq.m.
C60: Grid G-H | D60: 2 | E60: 8 | F60: 0.3 | G60: 1 | H60: 6.5 | I60: 1.05 | J60: =+D60*E60*F60*G60*H60*I60 -> 32.76 | K60: sq.m.
B61: b.2 | C61: 2B2
C62: Grid E | D62: 2 | E62: 8 | F62: 0.25 | G62: 1 | H62: 1.5 | I62: 1.05 | J62: =+D62*E62*F62*G62*H62*I62 -> 6.3 | K62: sq.m.
C63: Grid F | D63: 2 | E63: 8 | F63: 0.25 | G63: 1 | H63: 1.5 | I63: 1.05 | J63: =+D63*E63*F63*G63*H63*I63 -> 6.3 | K63: sq.m.
C64: Grid G | D64: 2 | E64: 8 | F64: 0.25 | G64: 1 | H64: 1.5 | I64: 1.05 | J64: =+D64*E64*F64*G64*H64*I64 -> 6.3 | K64: sq.m.
C65: Grid H | D65: 2 | E65: 8 | F65: 0.25 | G65: 1 | H65: 1.5 | I65: 1.05 | J65: =+D65*E65*F65*G65*H65*I65 -> 6.3 | K65: sq.m.
...

Sheet IX.
B3: Project Name: | C3: Proposed /Construction of Adidtional Footing/ Column & Beam for Archbishop's Palace
B4: Location: | C4: D. Jakosalem St., Cebu City
B6: Item No.: | C6: =+BOQ!B101 -> 0
B7: Item of Works: | C7: =+BOQ!C101 -> Plumbing Works
B9: Quatity: | C9: 1 | D9: Unit: | E9: lot
B12: Detailed Unit Price Analysis:
B13: A. MATERIALS
B14: DESCRIPTION | D14: QUANTITY | E14: UNIT | F14: UNIT COST | G14: AMOUNT
G15: =+D15*F15 -> 0
B16: Plumbing Works:Pipes, Fittings, Fixtures and Other Needed Items (Inclusions of Labor & Equipment Used) | D16: 1 | E16: 1 | F16: =+(BOQ!K164*0.2)/2 -> 0 | G16: =+D16*E16*F16 -> 0
G17: =+D17*F17 -> 0
G18: =+D18*F18 -> 0
G19: =+D19*F19 -> 0
B21: Total Materials Cost: | G21: =+SUM(G15:G20) -> 0
B22: B. EQUIPMENT
B23: DESCRIPTION | D23: QTY | E23: RATE/DAY | F23: NO. OF DAYS | G23: AMOUNT
B27: Total Equipment Cost: | G27: =+SUM(G24:G26) -> 0
B28: C. MANPOWER
B29: DESCRIPTION | D29: QTY | E29: RATE/DAY | F29: NO. OF DAYS | G29: AMOUNT
B35: Total Manpower Cost: | G35: =+SUM(G30:G34) -> 0
B36: TOTAL DIRECT COST (A+B+C): | G36: =+SUM(G21,G27,G35) -> 0
B38: D. Mobilization/Demobilization | E38: 0.01 | F38: of Direct Cost | G38: =+G36*E38 -> 0
B39: E. Overhead, Miscellaneous & Contingencies (OCM) | E39: 0.12 | F39: of Direct Cost | G39: =+G36*E39 -> 0
B40: F. Contractor's Profit | E40: 0.08 | F40: of Direct Cost | G40: =+G36*E40 -> 0
B41: G. VAT | E41: 0.05 | F41: of (DC+OCM+CP) | G41: =+E41*(G36+G39+G40) -> 0
B42: TOTAL INDIRECT COST: | G42: =+SUM(G38:G41) -> 0
B44: TOTAL CONSTRUCTION COST: | G44: =+SUM(G36,G42) -> 0
B45: Unit Cost: | G45: =+G44/C9 -> 0

Sheet X.
B3: Project Name: | C3: Proposed /Construction of Adidtional Footing/ Column & Beam for Archbishop's Palace
B4: Location: | C4: D. Jakosalem St., Cebu City
B6: Item No.: | C6: =+BOQ!B118 -> 0
B7: Item of Works: | C7: =+BOQ!C118 -> Electrical Works
B9: Quatity: | C9: 1 | D9: Unit: | E9: lot
B12: Detailed Unit Price Analysis:
B13: A. MATERIALS
B14: DESCRIPTION | D14: QUANTITY | E14: UNIT | F14: UNIT COST | G14: AMOUNT
G15: =+D15*F15 -> 0
B16: Electrical Works: Conduits, Fittings, Fixtures and Other Needed Items (Inclusions of Labor & Equipment Used) | D16: 1 | E16: 1 | F16: =+(BOQ!K164*0.15)/2 -> 0 | G16: =+D16*E16*F16 -> 0
G17: =+D17*F17 -> 0
G18: =+D18*F18 -> 0
G19: =+D19*F19 -> 0
B21: Total Materials Cost: | G21: =+SUM(G15:G20) -> 0
B22: B. EQUIPMENT
B23: DESCRIPTION | D23: QTY | E23: RATE/DAY | F23: NO. OF DAYS | G23: AMOUNT
B27: Total Equipment Cost: | G27: =+SUM(G24:G26) -> 0
B28: C. MANPOWER
B29: DESCRIPTION | D29: QTY | E29: RATE/DAY | F29: NO. OF DAYS | G29: AMOUNT
B35: Total Manpower Cost: | G35: =+SUM(G30:G34) -> 0
B36: TOTAL DIRECT COST (A+B+C): | G36: =+SUM(G21,G27,G35) -> 0
B38: D. Mobilization/Demobilization | E38: 0.01 | F38: of Direct Cost | G38: =+G36*E38 -> 0
B39: E. Overhead, Miscellaneous & Contingencies (OCM) | E39: 0.12 | F39: of Direct Cost | G39: =+G36*E39 -> 0
B40: F. Contractor's Profit | E40: 0.08 | F40: of Direct Cost | G40: =+G36*E40 -> 0
B41: G. VAT | E41: 0.05 | F41: of (DC+OCM+CP) | G41: =+E41*(G36+G39+G40) -> 0
B42: TOTAL INDIRECT COST: | G42: =+SUM(G38:G41) -> 0
B44: TOTAL CONSTRUCTION COST: | G44: =+SUM(G36,G42) -> 0
B45: Unit Cost: | G45: =+G44/C9 -> 0

Sheet XI.
B3: Project Name: | C3: Proposed /Construction of Adidtional Footing/ Column & Beam for Archbishop's Palace
B4: Location: | C4: D. Jakosalem St., Cebu City
B6: Item No.: | C6: =+BOQ!B142 -> 0
B7: Item of Works: | C7: =+BOQ!C142 -> Roofing Works (half only)
B9: Quatity: | C9: 1 | D9: Unit: | E9: lot
B12: Detailed Unit Price Analysis:
B13: A. MATERIALS
B14: DESCRIPTION | D14: QUANTITY | E14: UNIT | F14: UNIT COST | G14: AMOUNT
G15: =+D15*F15 -> 0
B16: Furnitures: Kitchen, Bedrooms & Cabinets | D16: 1 | E16: 1 | F16: 250000 | G16: =+D16*E16*F16 -> 250000
G17: =+D17*F17 -> 0
G18: =+D18*F18 -> 0
G19: =+D19*F19 -> 0
B21: Total Materials Cost: | G21: =+SUM(G15:G20) -> 250000
B22: B. EQUIPMENT
B23: DESCRIPTION | D23: QTY | E23: RATE/DAY | F23: NO. OF DAYS | G23: AMOUNT
B27: Total Equipment Cost: | G27: =+SUM(G24:G26) -> 0
B28: C. MANPOWER
B29: DESCRIPTION | D29: QTY | E29: RATE/DAY | F29: NO. OF DAYS | G29: AMOUNT
B35: Total Manpower Cost: | G35: =+SUM(G30:G34) -> 0
B36: TOTAL DIRECT COST (A+B+C): | G36: =+SUM(G21,G27,G35) -> 250000
B38: D. Mobilization/Demobilization | E38: 0.01 | F38: of Direct Cost | G38: =+G36*E38 -> 2500
B39: E. Overhead, Miscellaneous & Contingencies (OCM) | E39: 0.12 | F39: of Direct Cost | G39: =+G36*E39 -> 30000
B40: F. Contractor's Profit | E40: 0.08 | F40: of Direct Cost | G40: =+G36*E40 -> 20000
B41: G. VAT | E41: 0.05 | F41: of (DC+OCM+CP) | G41: =+E41*(G36+G39+G40) -> 15000
B42: TOTAL INDIRECT COST: | G42: =+SUM(G38:G41) -> 67500
B44: TOTAL CONSTRUCTION COST: | G44: =+SUM(G36,G42) -> 317500
B45: Unit Cost: | G45: =+G44/C9 -> 317500
